Workbook

Sheet Leia-me
A1: BDRs da B3 — levantamento BRAPI
A3: Fonte | B3: BRAPI (brapi.dev) — /api/v2/tickers?subType=bdr e /api/v2/stocks/quote (1 ativo por chamada)
A4: Plano | B4: Gratuito (token do PrimeVest) — 892 requisições da cota mensal
A5: Coletado em | B5: 24/09/2026 (madrugada), com a cotação do fechamento de 23/09/2026
A6: Horário da cotação | B6: 23/09/2026 18:31 (Brasília) — regularMarketTime 21:31:30 UTC, igual para todos
A7: Universo | B7: 892 BDRs: 657 de ação (sufixo 34), 223 de ETF (39), 6 com sufixo 31, 2 com 32, 2 com 33, 1 com 35 (Alphabet classe C) e 1 unit (PPLA11). Todos marcados ativos pela BRAPI
A8: Filtro | B8: Nenhum BDR excluído: diferente dos ETFs, a lista não trouxe duplicatas nem ativos de outro tipo. Casos estranhos estão na coluna "Observação"
A9: Catálogo PrimeVest | B9: O tipo BDR existe (price_source BRAPI), mas o catálogo não tem nenhum BDR cadastrado
A10: Setor | B10: A BRAPI dá o setor em inglês (padrão internacional); a coluna "Setor (pt-BR)" é tradução nossa. Subsetor vem vazio em 891 de 892
A11: Proporção | B11: "Ações por BDR" vem do texto "Repr X Sh" do nome longo da BRAPI; 18 BDRs não trazem a proporção
A12: Categorias | B12: Colunas "Sugestão — …" seguem a regra decidida para ETFs (description / name / segment). É sugestão: nada decidido para BDR ainda
A13: Dividendos | B13: Não disponíveis no plano gratuito

Sheet BDRs (892)
A1: Ticker | B1: Empresa / fundo | C1: Classe | D1: Sufixo | E1: Setor (pt-BR) | F1: Setor (BRAPI) | G1: Patrocínio (BRAPI) | H1: Lastro | I1: Ações por BDR | J1: BDRs por ação | K1: Preço (R$) | L1: Variação (R$) | M1: Variação dia | N1: Abertura (R$) | O1: Mínima dia (R$) | P1: Máxima dia (R$) | Q1: Fech. anterior (R$) | R1: Volume (BDRs) | S1: Volume financeiro aprox. (R$) | T1: Mín. 52 semanas (R$) | U1: Máx. 52 semanas (R$) | V1: Posição na faixa 52s | W1: Distância da máx. 52s | X1: Valor de mercado da empresa (R$ mi) | Y1: Sugestão — categoria description | Z1: Sugestão — categoria name | AA1: Sugestão — segment | AB1: Observação | AC1: Logo (URL) | AD1: Cotação em
A2: A1AP34 | B2: Advance Auto Parts, Inc. | C2: BDR de ação | D2: 34 | E2: Varejo | F2: Retail Trade | G2: Não patrocinado | H2: Ação | I2: 0.0625 | J2: =IF(I2="","",1/I2) -> 16 | K2: 13.36 | L2: -0.23 | M2: -0.0169 | N2: 13.94 | O2: 13.36 | P2: 13.94 | Q2: 13.36 | R2: 1113 | S2: =K2*R2 -> 14869.68 | T2: 12.9 | U2: 21.3 | V2: =IF(U2-T2=0,"",(K2-T2)/(U2-T2)) -> 0.054761905 | W2: =IF(U2=0,"",K2/U2-1) -> -0.37276995 | X2: 13187 | Y2: Varejo | Z2: VAREJO | AA2: Retail Trade | AC2: https://icons.brapi.dev/icons/A1AP34.svg | AD2: 46288.772
A3: A1CR34 | B3: Amcor PLC | C3: BDR de ação | D3: 34 | E3: Indústria de transformação | F3: Process Industries | G3: Não patrocinado | H3: Ação | I3: 1 | J3: =IF(I3="","",1/I3) -> 1 | K3: 216.92 | L3: -0.66 | M3: -0.003 | N3: 215.88 | O3: 215.88 | P3: 217.36 | Q3: 216.92 | R3: 146 | S3: =K3*R3 -> 31670.32 | T3: 182.02 | U3: 266.06 | V3: =IF(U3-T3=0,"",(K3-T3)/(U3-T3)) -> 0.41527844 | W3: =IF(U3=0,"",K3/U3-1) -> -0.18469518 | X3: 102312 | Y3: Indústria de transformação | Z3: INDUSTRIA_DE_TRANSFORMACAO | AA3: Process Industries | AC3: https://icons.brapi.dev/icons/A1CR34.svg | AD3: 46288.772
A4: A1DC34 | B4: Agree Realty Corp | C4: BDR de ação | D4: 34 | E4: Finanças | F4: Finance | G4: Não patrocinado | H4: Ação | I4: 0.125 | J4: =IF(I4="","",1/I4) -> 8 | K4: 43.31 | L4: 0 | M4: 0 | N4: 43.31 | O4: 43.31 | P4: 43.31 | Q4: 43.31 | R4: 12 | S4: =K4*R4 -> 519.72 | T4: 43.31 | U4: 52.91 | V4: =IF(U4-T4=0,"",(K4-T4)/(U4-T4)) -> 0 | W4: =IF(U4=0,"",K4/U4-1) -> -0.18144018 | X4: 42852 | Y4: Finanças | Z4: FINANCAS | AA4: Finance | AC4: https://icons.brapi.dev/icons/A1DC34.svg | AD4: 46288.772
A5: A1DI34 | B5: Analog Devices Inc | C5: BDR de ação | D5: 34 | E5: Tecnologia eletrônica | F5: Electronic Technology | G5: Não patrocinado | H5: Ação | I5: 0.025 | J5: =IF(I5="","",1/I5) -> 40 | K5: 49.7 | L5: 0.35 | M5: 0.0071 | N5: 49.85 | O5: 49 | P5: 49.85 | Q5: 49.7 | R5: 235 | S5: =K5*R5 -> 11679.5 | T5: 30.85 | U5: 57.288 | V5: =IF(U5-T5=0,"",(K5-T5)/(U5-T5)) -> 0.71298888 | W5: =IF(U5=0,"",K5/U5-1) -> -0.13245357 | X5: 968065 | Y5: Tecnologia eletrônica | Z5: TECNOLOGIA_ELETRONICA | AA5: Electronic Technology | AC5: https://icons.brapi.dev/icons/A1DI34.svg | AD5: 46288.772
A6: A1DM34 | B6: Archer Daniels Midland Company | C6: BDR de ação | D6: 34 | E6: Indústria de transformação | F6: Process Industries | G6: Não patrocinado | H6: Ação | I6: 0.125 | J6: =IF(I6="","",1/I6) -> 8 | K6: 53.45 | L6: 0.44 | M6: 0.0083 | N6: 53.45 | O6: 53.45 | P6: 53.45 | Q6: 53.45 | R6: 9 | S6: =K6*R6 -> 481.05 | T6: 37.2 | U6: 58.03 | V6: =IF(U6-T6=0,"",(K6-T6)/(U6-T6)) -> 0.78012482 | W6: =IF(U6=0,"",K6/U6-1) -> -0.078924694 | X6: 203094 | Y6: Indústria de transformação | Z6: INDUSTRIA_DE_TRANSFORMACAO | AA6: Process Industries | AC6: https://icons.brapi.dev/icons/A1DM34.svg | AD6: 46288.772
A7: A1EG34 | B7: Aegon Ltd. | C7: BDR de ação | D7: 34 | E7: Finanças | F7: Finance | G7: Não patrocinado | H7: ADR | I7: 0.25 | J7: =IF(I7="","",1/I7) -> 4 | K7: 45.65 | L7: 0 | M7: 0 | N7: 45.65 | O7: 45.65 | P7: 45.65 | Q7: 45.65 | R7: 16 | S7: =K7*R7 -> 730.4 | T7: 33.81 | U7: 49.75 | V7: =IF(U7-T7=0,"",(K7-T7)/(U7-T7)) -> 0.74278545 | W7: =IF(U7=0,"",K7/U7-1) -> -0.08241206 | X7: 68553 | Y7: Finanças | Z7: FINANCAS | AA7: Finance | AC7: https://icons.brapi.dev/icons/A1EG34.svg | AD7: 46288.772
A8: A1EP34 | B8: American Electric Power Inc | C8: BDR de ação | D8: 34 | E8: Utilidade pública | F8: Utilities | G8: Não patrocinado | H8: Ação | I8: 0.1 | J8: =IF(I8="","",1/I8) -> 10 | K8: 61.44 | L8: -0.18 | M8: -0.0029 | N8: 60.96 | O8: 60.96 | P8: 61.44 | Q8: 61.44 | R8: 819 | S8: =K8*R8 -> 50319.36 | T8: 59.008 | U8: 72.4 | V8: =IF(U8-T8=0,"",(K8-T8)/(U8-T8)) -> 0.18160096 | W8: =IF(U8=0,"",K8/U8-1) -> -0.15138122 | X8: 335080 | Y8: Utilidade pública | Z8: UTILIDADE_PUBLICA | AA8: Utilities | AC8: https://icons.brapi.dev/icons/A1EP34.svg | AD8: 46288.772
A9: A1ES34 | B9: AES Corporation | C9: BDR de ação | D9: 34 | E9: Utilidade pública | F9: Utilities | G9: Não patrocinado | H9: Ação | I9: 1 | J9: =IF(I9="","",1/I9) -> 1 | K9: 76.24 | L9: 0.56 | M9: 0.0074 | N9: 76.24 | O9: 76.24 | P9: 76.24 | Q9: 76.24 | R9: 1 | S9: =K9*R9 -> 76.24 | T9: 69.65 | U9: 90.63 | V9: =IF(U9-T9=0,"",(K9-T9)/(U9-T9)) -> 0.31410867 | W9: =IF(U9=0,"",K9/U9-1) -> -0.15877745 | X9: 54110 | Y9: Utilidade pública | Z9: UTILIDADE_PUBLICA | AA9: Utilities | AC9: https://icons.brapi.dev/icons/A1ES34.svg | AD9: 46288.772
A10: A1GI34 | B10: Agilent Technologies Inc | C10: BDR de ação | D10: 34 | E10: Tecnologia em saúde | F10: Health Technology | G10: Não patrocinado | H10: Ação | I10: 0.1 | J10: =IF(I10="","",1/I10) -> 10 | K10: 82.5 | L10: 6.74 | M10: 0.089 | N10: 82.24 | O10: 82.24 | P10: 82.55 | Q10: 82.5 | R10: 5066 | S10: =K10*R10 -> 417945 | T10: 54.834 | U10: 82.55 | V10: =IF(U10-T10=0,"",(K10-T10)/(U10-T10)) -> 0.99819599 | W10: =IF(U10=0,"",K10/U10-1) -> -0.00060569352 | X10: 241328 | Y10: Tecnologia em saúde | Z10: TECNOLOGIA_EM_SAUDE | AA10: Health Technology | AC10: https://icons.brapi.dev/icons/A1GI34.svg | AD10: 46288.772
A11: A1GN34 | B11: Allegion PLC | C11: BDR de ação | D11: 34 | E11: Bens de consumo duráveis | F11: Consumer Durables | G11: Não patrocinado | H11: Ação | I11: 0.5 | J11: =IF(I11="","",1/I11) -> 2 | K11: 385.48 | L11: 37.19 | M11: 0.1068 | N11: 388.58 | O11: 385.48 | P11: 388.58 | Q11: 385.48 | R11: 2 | S11: =K11*R11 -> 770.96 | T11: 347.12 | U11: 440.13 | V11: =IF(U11-T11=0,"",(K11-T11)/(U11-T11)) -> 0.41242877 | W11: =IF(U11=0,"",K11/U11-1) -> -0.12416786 | X11: 66998 | Y11: Bens de consumo duráveis | Z11: BENS_DE_CONSUMO_DURAVEIS | AA11: Consumer Durables | AC11: https://icons.brapi.dev/icons/A1GN34.svg | AD11: 46288.772
A12: A1IV34 | B12: Apartment Investment and Management Company -A- | C12: BDR de ação | D12: 34 | E12: Finanças | F12: Finance | G12: Não patrocinado | J12: =IF(I12="","",1/I12) | K12: 11.2 | L12: -0.09 | M12: -0.008 | N12: 11.41 | O12: 10.9 | P12: 11.41 | Q12: 11.2 | R12: 1249 | S12: =K12*R12 -> 13988.8 | T12: 10.9 | U12: 44.5 | V12: =IF(U12-T12=0,"",(K12-T12)/(U12-T12)) -> 0.0089285714 | W12: =IF(U12=0,"",K12/U12-1) -> -0.74831461 | X12: 1605 | Y12: Finanças | Z12: FINANCAS | AA12: Finance | AB12: Proporção não informada pela BRAPI. | AC12: https://icons.brapi.dev/icons/A1IV34.svg | AD12: 46288.772
A13: A1KA34 | B13: Akamai Technologies, Inc. | C13: BDR de ação | D13: 34 | E13: Serviços de tecnologia | F13: Technology Services | G13: Não patrocinado | H13: Ação | I13: 0.0833 | J13: =IF(I13="","",1/I13) -> 12.004802 | K13: 51.4 | L13: 0.71 | M13: 0.014 | N13: 50.45 | O13: 48.94 | P13: 51.6 | Q13: 51.4 | R13: 41961 | S13: =K13*R13 -> 2156795.4 | T13: 32.24 | U13: 68.99 | V13: =IF(U13-T13=0,"",(K13-T13)/(U13-T13)) -> 0.52136054 | W13: =IF(U13=0,"",K13/U13-1) -> -0.25496449 | X13: 87039 | Y13: Serviços de tecnologia | Z13: SERVICOS_DE_TECNOLOGIA | AA13: Technology Services | AC13: https://icons.brapi.dev/icons/A1KA34.svg | AD13: 46288.772
A14: A1LB34 | B14: Albemarle Corporation | C14: BDR de ação | D14: 34 | E14: Indústria de transformação | F14: Process Industries | G14: Não patrocinado | H14: Ação | I14: 0.04166667 | J14: =IF(I14="","",1/I14) -> 23.999998 | K14: 25.25 | L14: 0.34 | M14: 0.0136 | N14: 24.58 | O14: 24.04 | P14: 25.25 | Q14: 24.6 | R14: 2392 | S14: =K14*R14 -> 60398 | T14: 17.6 | U14: 45.15 | V14: =IF(U14-T14=0,"",(K14-T14)/(U14-T14)) -> 0.27767695 | W14: =IF(U14=0,"",K14/U14-1) -> -0.44075305 | X14: 70537 | Y14: Indústria de transformação | Z14: INDUSTRIA_DE_TRANSFORMACAO | AA14: Process Industries | AC14: https://icons.brapi.dev/icons/A1LB34.svg | AD14: 46288.772
A15: A1LG34 | B15: Align Technology, Inc. | C15: BDR de ação | D15: 34 | E15: Tecnologia em saúde | F15: Health Technology | G15: Não patrocinado | J15: =IF(I15="","",1/I15) | K15: 192.28 | L15: -5.89 | M15: -0.0297 | N15: 191.14 | O15: 189.24 | P15: 192.28 | Q15: 192.28 | R15: 6 | S15: =K15*R15 -> 1153.68 | T15: 164.56 | U15: 248.5 | V15: =IF(U15-T15=0,"",(K15-T15)/(U15-T15)) -> 0.33023588 | W15: =IF(U15=0,"",K15/U15-1) -> -0.22623742 | X15: 55730 | Y15: Tecnologia em saúde | Z15: TECNOLOGIA_EM_SAUDE | AA15: Health Technology | AB15: Proporção não informada pela BRAPI. | AC15: https://icons.brapi.dev/icons/A1LG34.svg | AD15: 46288.772
A16: A1LK34 | B16: Alaska Air Group, Inc. | C16: BDR de ação | D16: 34 | E16: Transporte | F16: Transportation | G16: Não patrocinado | H16: Ação | I16: 1 | J16: =IF(I16="","",1/I16) -> 1 | K16: 209.16 | L16: 2.1 | M16: 0.0101 | N16: 207.06 | O16: 207.06 | P16: 209.16 | Q16: 209.16 | R16: 3 | S16: =K16*R16 -> 627.48 | T16: 174.72 | U16: 312 | V16: =IF(U16-T16=0,"",(K16-T16)/(U16-T16)) -> 0.25087413 | W16: =IF(U16=0,"",K16/U16-1) -> -0.32961538 | X16: 23937 | Y16: Transporte | Z16: TRANSPORTE | AA16: Transportation | AC16: https://icons.brapi.dev/icons/A1LK34.svg | AD16: 46288.772
A17: A1LL34 | B17: Bread Financial Holdings, Inc. | C17: BDR de ação | D17: 34 | E17: Finanças | F17: Finance | G17: Não patrocinado | H17: Ação | I17: 0.25 | J17: =IF(I17="","",1/I17) -> 4 | K17: 130.39 | L17: -8.49 | M17: -0.0611 | N17: 130 | O17: 129.98 | P17: 131.04 | Q17: 130.39 | R17: 19 | S17: =K17*R17 -> 2477.41 | T17: 72.3 | U17: 148.5 | V17: =IF(U17-T17=0,"",(K17-T17)/(U17-T17)) -> 0.76233596 | W17: =IF(U17=0,"",K17/U17-1) -> -0.12195286 | X17: 20191 | Y17: Finanças | Z17: FINANCAS | AA17: Finance | AC17: https://icons.brapi.dev/icons/A1LL34.svg | AD17: 46288.772
A18: A1LN34 | B18: Alnylam Pharmaceuticals, Inc | C18: BDR de ação | D18: 34 | E18: Tecnologia em saúde | F18: Health Technology | G18: Não patrocinado | H18: Ação | I18: 0.05 | J18: =IF(I18="","",1/I18) -> 20 | K18: 63.72 | L18: 0.66 | M18: 0.0105 | N18: 63.72 | O18: 63.72 | P18: 63.72 | Q18: 63.72 | R18: 70 | S18: =K18*R18 -> 4460.4 | T18: 50.25 | U18: 132.4 | V18: =IF(U18-T18=0,"",(K18-T18)/(U18-T18)) -> 0.16396835 | W18: =IF(U18=0,"",K18/U18-1) -> -0.51873112 | X18: 172329 | Y18: Tecnologia em saúde | Z18: TECNOLOGIA_EM_SAUDE | AA18: Health Technology | AC18: https://icons.brapi.dev/icons/A1LN34.svg | AD18: 46288.772
A19: A1MD34 | B19: Advanced Micro Devices, Inc. | C19: BDR de ação | D19: 34 | E19: Tecnologia eletrônica | F19: Electronic Technology | G19: Não patrocinado | H19: Ação | I19: 0.125 | J19: =IF(I19="","",1/I19) -> 8 | K19: 396 | L19: -0.85 | M19: -0.0021 | N19: 397.29 | O19: 391.15 | P19: 399.51 | Q19: 396.26 | R19: 36230 | S19: =K19*R19 -> 14347080 | T19: 103.35 | U19: 399.51 | V19: =IF(U19-T19=0,"",(K19-T19)/(U19-T19)) -> 0.9881483 | W19: =IF(U19=0,"",K19/U19-1) -> -0.0087857626 | X19: 5211305 | Y19: Tecnologia eletrônica | Z19: TECNOLOGIA_ELETRONICA | AA19: Electronic Technology | AC19: https://icons.brapi.dev/icons/A1MD34.svg | AD19: 46288.772
A20: A1ME34 | B20: AMETEK, Inc. | C20: BDR de ação | D20: 34 | E20: Bens de produção | F20: Producer Manufacturing | G20: Não patrocinado | J20: =IF(I20="","",1/I20) | K20: 52.05 | L20: 2.45 | M20: 0.0494 | N20: 52.44 | O20: 52.05 | P20: 52.44 | Q20: 52.05 | R20: 201 | S20: =K20*R20 -> 10462.05 | T20: 40.37 | U20: 53.99 | V20: =IF(U20-T20=0,"",(K20-T20)/(U20-T20)) -> 0.85756241 | W20: =IF(U20=0,"",K20/U20-1) -> -0.03593258 | X20: 287938 | Y20: Bens de produção | Z20: BENS_DE_PRODUCAO | AA20: Producer Manufacturing | AB20: Proporção não informada pela BRAPI. | AC20: https://icons.brapi.dev/icons/A1ME34.svg | AD20: 46288.772
A21: A1MP34 | B21: Ameriprise Financial Inc | C21: BDR de ação | D21: 34 | E21: Finanças | F21: Finance | G21: Não patrocinado | H21: Ação | I21: 0.025 | J21: =IF(I21="","",1/I21) -> 40 | K21: 65.58 | L21: -4.56 | M21: -0.065 | N21: 64.46 | O21: 64.46 | P21: 65.58 | Q21: 65.58 | R21: 45 | S21: =K21*R21 -> 2951.1 | T21: 55 | U21: 74.13 | V21: =IF(U21-T21=0,"",(K21-T21)/(U21-T21)) -> 0.55305802 | W21: =IF(U21=0,"",K21/U21-1) -> -0.11533792 | X21: 231624 | Y21: Finanças | Z21: FINANCAS | AA21: Finance | AC21: https://icons.brapi.dev/icons/A1MP34.svg | AD21: 46288.772
A22: A1MT34 | B22: Applied Materials, Inc. | C22: BDR de ação | D22: 34 | E22: Bens de produção | F22: Producer Manufacturing | G22: Não patrocinado | H22: Ação | I22: 0.1 | J22: =IF(I22="","",1/I22) -> 10 | K22: 246 | L22: 4.8 | M22: 0.0199 | N22: 244.1 | O22: 237.45 | P22: 246 | Q22: 244.7 | R22: 4117 | S22: =K22*R22 -> 1012782 | T22: 104.97 | U22: 382.67 | V22: =IF(U22-T22=0,"",(K22-T22)/(U22-T22)) -> 0.5078502 | W22: =IF(U22=0,"",K22/U22-1) -> -0.35714846 | X22: 1918849 | Y22: Bens de produção | Z22: BENS_DE_PRODUCAO | AA22: Producer Manufacturing | AC22: https://icons.brapi.dev/icons/A1MT34.svg | AD22: 46288.772
A23: A1NE34 | B23: Arista Networks Inc | C23: BDR de ação | D23: 34 | E23: Tecnologia eletrônica | F23: Electronic Technology | G23: Não patrocinado | H23: Ação | I23: 0.25 | J23: =IF(I23="","",1/I23) -> 4 | K23: 262.6 | L23: 0.78 | M23: 0.003 | N23: 260.53 | O23: 259.48 | P23: 263.15 | Q23: 262.6 | R23: 435 | S23: =K23*R23 -> 114231 | T23: 151.97 | U23: 272.91 | V23: =IF(U23-T23=0,"",(K23-T23)/(U23-T23)) -> 0.91475112 | W23: =IF(U23=0,"",K23/U23-1) -> -0.037778022 | X23: 1324415 | Y23: Tecnologia eletrônica | Z23: TECNOLOGIA_ELETRONICA | AA23: Electronic Technology | AC23: https://icons.brapi.dev/icons/A1NE34.svg | AD23: 46288.772
A24: A1ON34 | B24: Aon PLC | C24: BDR de ação | D24: 34 | E24: Finanças | F24: Finance | G24: Não patrocinado | H24: Ação | I24: 0.041667 | J24: =IF(I24="","",1/I24) -> 23.999808 | K24: 60.95 | L24: 0.2 | M24: 0.0033 | N24: 60.95 | O24: 60.95 | P24: 60.95 | Q24: 60.95 | R24: 1 | S24: =K24*R24 -> 60.95 | T24: 60.4 | U24: 81.250002 | V24: =IF(U24-T24=0,"",(K24-T24)/(U24-T24)) -> 0.026378895 | W24: =IF(U24=0,"",K24/U24-1) -> -0.24984617 | X24: 310589 | Y24: Finanças | Z24: FINANCAS | AA24: Finance | AC24: https://icons.brapi.dev/icons/A1ON34.svg | AD24: 46288.772
A25: A1PA34 | B25: APA Corporation | C25: BDR de ação | D25: 34 | E25: Energia (petróleo, gás e carvão) | F25: Energy Minerals | G25: Não patrocinado | H25: Ação | I25: 1 | J25: =IF(I25="","",1/I25) -> 1 | K25: 225.94 | L25: 5.59 | M25: 0.0254 | N25: 225.94 | O25: 225.94 | P25: 225.94 | Q25: 225.94 | R25: 6 | S25: =K25*R25 -> 1355.64 | T25: 118 | U25: 234.37 | V25: =IF(U25-T25=0,"",(K25-T25)/(U25-T25)) -> 0.92755865 | W25: =IF(U25=0,"",K25/U25-1) -> -0.035968767 | X25: 75844 | Y25: Energia (petróleo, gás e carvão) | Z25: ENERGIA | AA25: Energy Minerals | AC25: https://icons.brapi.dev/icons/A1PA34.svg | AD25: 46288.772
A26: A1PD34 | B26: Air Products & Chemicals Inc | C26: BDR de ação | D26: 34 | E26: Indústria de transformação | F26: Process Industries | G26: Não patrocinado | H26: Ação | I26: 0.041667 | J26: =IF(I26="","",1/I26) -> 23.999808 | K26: 60.56 | L26: -1.9 | M26: -0.0304 | N26: 60.56 | O26: 60.56 | P26: 60.56 | Q26: 60.56 | R26: 3 | S26: =K26*R26 -> 181.68 | T26: 51.016668 | U26: 66.99 | V26: =IF(U26-T26=0,"",(K26-T26)/(U26-T26)) -> 0.59745406 | W26: =IF(U26=0,"",K26/U26-1) -> -0.095984475 | X26: 328057 | Y26: Indústria de transformação | Z26: INDUSTRIA_DE_TRANSFORMACAO | AA26: Process Industries | AC26: https://icons.brapi.dev/icons/A1PD34.svg | AD26: 46288.772
A27: A1PH34 | B27: Amphenol Corporation (New) | C27: BDR de ação | D27: 34 | E27: Tecnologia eletrônica | F27: Electronic Technology | G27: Não patrocinado | H27: Ação | I27: 0.083333 | J27: =IF(I27="","",1/I27) -> 12.000048 | K27: 35.44 | L27: 0.1 | M27: 0.0028 | N27: 35.63 | O27: 35.05 | P27: 35.63 | Q27: 35.44 | R27: 3940 | S27: =K27*R27 -> 139633.6 | T27: 24.72 | U27: 68.2 | V27: =IF(U27-T27=0,"",(K27-T27)/(U27-T27)) -> 0.24655013 | W27: =IF(U27=0,"",K27/U27-1) -> -0.48035191 | X27: 1045449 | Y27: Tecnologia eletrônica | Z27: TECNOLOGIA_ELETRONICA | AA27: Electronic Technology | AC27: https://icons.brapi.dev/icons/A1PH34.svg | AD27: 46288.772
A28: A1PL34 | B28: Applied Digital Corporation | C28: BDR de ação | D28: 34 | E28: Serviços de tecnologia | F28: Technology Services | G28: Não patrocinado | H28: Ação | I28: 1 | J28: =IF(I28="","",1/I28) -> 1 | K28: 144.6 | L28: -3.1 | M28: -0.021 | N28: 147.75 | O28: 144.15 | P28: 147.75 | Q28: 144.61 | R28: 154 | S28: =K28*R28 -> 22268.4 | T28: 104.36 | U28: 251.81 | V28: =IF(U28-T28=0,"",(K28-T28)/(U28-T28)) -> 0.27290607 | W28: =IF(U28=0,"",K28/U28-1) -> -0.42575752 | X28: 42572 | Y28: Serviços de tecnologia | Z28: SERVICOS_DE_TECNOLOGIA | AA28: Technology Services | AC28: https://icons.brapi.dev/icons/A1PL34.svg | AD28: 46288.772
A29: A1PO34 | B29: Apollo Global Management Inc | C29: BDR de ação | D29: 34 | E29: Finanças | F29: Finance | G29: Não patrocinado | H29: Ação | I29: 0.06666667 | J29: =IF(I29="","",1/I29) -> 14.999999 | K29: 42.81 | L29: 0.52 | M29: 0.0123 | N29: 42.29 | O29: 42.29 | P29: 43.21 | Q29: 42.81 | R29: 875 | S29: =K29*R29 -> 37458.75 | T29: 34.5 | U29: 56.2 | V29: =IF(U29-T29=0,"",(K29-T29)/(U29-T29)) -> 0.38294931 | W29: =IF(U29=0,"",K29/U29-1) -> -0.23825623 | X29: 375210 | Y29: Finanças | Z29: FINANCAS | AA29: Finance | AC29: https://icons.brapi.dev/icons/A1PO34.svg | AD29: 46288.772
A30: A1PP34 | B30: AppLovin Corp. | C30: BDR de ação | D30: 34 | E30: Serviços de tecnologia | F30: Technology Services | G30: (não informado) | H30: Ação | I30: 0.03125 | J30: =IF(I30="","",1/I30) -> 32 | K30: 50.97 | L30: -1.24 | M30: -0.0238 | N30: 52.74 | O30: 49.18 | P30: 52.74 | Q30: 50.97 | R30: 4417 | S30: =K30*R30 -> 225134.49 | T30: 48 | U30: 127.88 | V30: =IF(U30-T30=0,"",(K30-T30)/(U30-T30)) -> 0.037180771 | W30: =IF(U30=0,"",K30/U30-1) -> -0.60142321 | X30: 562998 | Y30: Serviços de tecnologia | Z30: SERVICOS_DE_TECNOLOGIA | AA30: Technology Services | AC30: https://icons.brapi.dev/icons/A1PP34.svg | AD30: 46288.772
A31: A1RC34 | B31: Arcos Dorados Holdings Inc | C31: BDR de ação | D31: 34 | E31: Serviços ao consumidor | F31: Consumer Services | G31: Não patrocinado | H31: Ação | I31: 1 | J31: =IF(I31="","",1/I31) -> 1 | K31: 39.04 | L31: -3.04 | M31: -0.0722 | N31: 39.7 | O31: 39.04 | P31: 39.7 | Q31: 39.04 | R31: 204 | S31: =K31*R31 -> 7964.16 | T31: 35.28 | U31: 46.9 | V31: =IF(U31-T31=0,"",(K31-T31)/(U31-T31)) -> 0.32358003 | W31: =IF(U31=0,"",K31/U31-1) -> -0.16759062 | X31: 8125 | Y31: Serviços ao consumidor | Z31: SERVICOS_AO_CONSUMIDOR | AA31: Consumer Services | AC31: https://icons.brapi.dev/icons/A1RC34.svg | AD31: 46288.772
A32: A1RE34 | B32: Alexandria Real Estate Equities Inc | C32: BDR de ação | D32: 34 | E32: Finanças | F32: Finance | G32: Não patrocinado | H32: Ação | I32: 0.25 | J32: =IF(I32="","",1/I32) -> 4 | K32: 66.98 | L32: -1.9 | M32: -0.0276 | N32: 68.88 | O32: 66.98 | P32: 68.88 | Q32: 66.98 | R32: 2359 | S32: =K32*R32 -> 158005.82 | T32: 49.66 | U32: 116 | V32: =IF(U32-T32=0,"",(K32-T32)/(U32-T32)) -> 0.26107929 | W32: =IF(U32=0,"",K32/U32-1) -> -0.42258621 | X32: 48021 | Y32: Finanças | Z32: FINANCAS | AA32: Finance | AC32: https://icons.brapi.dev/icons/A1RE34.svg | AD32: 46288.772
... A41: A1ZN34 | B41: AstraZeneca PLC | C41: BDR de ação | D41: 34 | E41: Tecnologia em saúde | F41: Health Technology | G41: Não patrocinado | H41: ADR | I41: 0.1666 | J41: =IF(I41="","",1/I41) -> 6.002401 | K41: 140.55 | L41: -8.38 | M41: -0.0563 | N41: 142.21 | O41: 140.55 | P41: 142.96 | Q41: 140.55 | R41: 522 | S41: =K41*R41 -> 73367.1 | T41: 130.02 | U41: 190.4 | V41: =IF(U41-T41=0,"",(K41-T41)/(U41-T41)) -> 0.1743955 | W41: =IF(U41=0,"",K41/U41-1) -> -0.26181723 | X41: 1341611 | Y41: Tecnologia em saúde | Z41: TECNOLOGIA_EM_SAUDE | AA41: Health Technology | AC41: https://icons.brapi.dev/icons/A1ZN34.svg | AD41: 46288.772
A42: A2FY34 | B42: Afya Limited | C42: BDR de ação | D42: 34 | E42: Serviços ao consumidor | F42: Consumer Services | G42: Não patrocinado | J42: =IF(I42="","",1/I42) | K42: 34.83 | L42: -0.03 | M42: -0.0009 | N42: 34.83 | O42: 34.83 | P42: 35.29 | Q42: 34.83 | R42: 2703 | S42: =K42*R42 -> 94145.49 | T42: 34 | U42: 44 | V42: =IF(U42-T42=0,"",(K42-T42)/(U42-T42)) -> 0.083 | W42: =IF(U42=0,"",K42/U42-1) -> -0.20840909 | X42: 6314 | Y42: Serviços ao consumidor | Z42: SERVICOS_AO_CONSUMIDOR | AA42: Consumer Services | AB42: Proporção não informada pela BRAPI. | AC42: https://icons.brapi.dev/icons/A2FY34.svg | AD42: 46288.772
A43: A2MB34 | B43: Ambarella, Inc. | C43: BDR de ação | D43: 34 | E43: Tecnologia eletrônica | F43: Electronic Technology | G43: Não patrocinado | H43: Ação | I43: 0.04 | J43: =IF(I43="","",1/I43) -> 25 | K43: 14.12 | L43: 0.29 | M43: 0.021 | N43: 13.5 | O43: 13.5 | P43: 14.13 | Q43: 14.12 | R43: 447 | S43: =K43*R43 -> 6311.64 | T43: 10.21 | U43: 20.3 | V43: =IF(U43-T43=0,"",(K43-T43)/(U43-T43)) -> 0.38751239 | W43: =IF(U43=0,"",K43/U43-1) -> -0.3044335 | X43: 15149 | Y43: Tecnologia eletrônica | Z43: TECNOLOGIA_ELETRONICA | AA43: Electronic Technology | AC43: https://icons.brapi.dev/icons/A2MB34.svg | AD43: 46288.772
A44: A2RE34 | B44: Ares Management Corporation | C44: BDR de ação | D44: 34 | E44: Finanças | F44: Finance | G44: Não patrocinado | H44: Ação | I44: 0.1 | J44: =IF(I44="","",1/I44) -> 10 | K44: 65.1 | L44: 0.24 | M44: 0.0037 | N44: 65.1 | O44: 65.1 | P44: 65.1 | Q44: 65.1 | R44: 2 | S44: =K44*R44 -> 130.2 | T44: 50 | U44: 94.31 | V44: =IF(U44-T44=0,"",(K44-T44)/(U44-T44)) -> 0.34078086 | W44: =IF(U44=0,"",K44/U44-1) -> -0.30972325 | X44: 142948 | Y44: Finanças | Z44: FINANCAS | AA44: Finance | AC44: https://icons.brapi.dev/icons/A2RE34.svg | AD44: 46288.772
A45: A2RR34 | B45: Arrowhead Pharmaceuticals, Inc. | C45: BDR de ação | D45: 34 | E45: Tecnologia em saúde | F45: Health Technology | G45: Não patrocinado | H45: Ação | I45: 0.125 | J45: =IF(I45="","",1/I45) -> 8 | K45: 45.8 | L45: 0 | M45: 0 | N45: 45.8 | O45: 45.8 | P45: 45.8 | Q45: 45.8 | R45: 5 | S45: =K45*R45 -> 229 | T45: 21.45 | U45: 59.95 | V45: =IF(U45-T45=0,"",(K45-T45)/(U45-T45)) -> 0.63246753 | W45: =IF(U45=0,"",K45/U45-1) -> -0.23603003 | X45: 51948 | Y45: Tecnologia em saúde | Z45: TECNOLOGIA_EM_SAUDE | AA45: Health Technology | AC45: https://icons.brapi.dev/icons/A2RR34.svg | AD45: 46288.772
A46: A2RW34 | B46: Arrows Electronics Inc | C46: BDR de ação | D46: 34 | E46: Distribuição | F46: Distribution Services | G46: Não patrocinado | H46: Ação | I46: 0.066666667 | J46: =IF(I46="","",1/I46) -> 15 | K46: 77.92 | L46: 2.32 | M46: 0.0307 | N46: 75.52 | O46: 75.52 | P46: 78.64 | Q46: 77.92 | R46: 13 | S46: =K46*R46 -> 1012.96 | T46: 38.03 | U46: 81.52 | V46: =IF(U46-T46=0,"",(K46-T46)/(U46-T46)) -> 0.91722235 | W46: =IF(U46=0,"",K46/U46-1) -> -0.044160942 | X46: 57791 | Y46: Distribuição | Z46: DISTRIBUICAO | AA46: Distribution Services | AC46: https://icons.brapi.dev/icons/A2RW34.svg | AD46: 46288.772
A47: A2SO34 | B47: Academy Sports and Outdoors Inc | C47: BDR de ação | D47: 34 | E47: Varejo | F47: Retail Trade | G47: Não patrocinado | H47: Ação | I47: 0.25 | J47: =IF(I47="","",1/I47) -> 4 | K47: 61.86 | L47: -0.3 | M47: -0.0048 | N47: 61.92 | O47: 61.86 | P47: 62.28 | Q47: 61.86 | R47: 3 | S47: =K47*R47 -> 185.58 | T47: 55 | U47: 78.35 | V47: =IF(U47-T47=0,"",(K47-T47)/(U47-T47)) -> 0.29379015 | W47: =IF(U47=0,"",K47/U47-1) -> -0.21046586 | X47: 15600 | Y47: Varejo | Z47: VAREJO | AA47: Retail Trade | AC47: https://icons.brapi.dev/icons/A2SO34.svg | AD47: 46288.772
A48: A2XO34 | B48: Axon Enterprise Inc | C48: BDR de ação | D48: 34 | E48: Tecnologia eletrônica | F48: Electronic Technology | G48: Não patrocinado | H48: Ação | I48: 0.055555556 | J48: =IF(I48="","",1/I48) -> 18 | K48: 129.47 | L48: -0.68 | M48: -0.0052 | N48: 129.47 | O48: 129.47 | P48: 129.47 | Q48: 129.47 | R48: 2 | S48: =K48*R48 -> 258.94 | T48: 94.6 | U48: 227.46 | V48: =IF(U48-T48=0,"",(K48-T48)/(U48-T48)) -> 0.26245672 | W48: =IF(U48=0,"",K48/U48-1) -> -0.43080102 | X48: 190962 | Y48: Tecnologia eletrônica | Z48: TECNOLOGIA_ELETRONICA | AA48: Electronic Technology | AC48: https://icons.brapi.dev/icons/A2XO34.svg | AD48: 46288.772
...

Sheet Resumo
A1: Por classe
A2: Classe | B2: Qtd. | C2: Volume financeiro aprox. (R$)
A3: BDR de ação | B3: =COUNTIF('BDRs (892)'!$C$2:$C$893,A3) -> 668 | C3: =SUMIF('BDRs (892)'!$C$2:$C$893,A3,'BDRs (892)'!$S$2:$S$893) -> 1.6592861e+09
A4: BDR de ETF | B4: =COUNTIF('BDRs (892)'!$C$2:$C$893,A4) -> 223 | C4: =SUMIF('BDRs (892)'!$C$2:$C$893,A4,'BDRs (892)'!$S$2:$S$893) -> 34417681
A5: Unit de BDR | B5: =COUNTIF('BDRs (892)'!$C$2:$C$893,A5) -> 1 | C5: =SUMIF('BDRs (892)'!$C$2:$C$893,A5,'BDRs (892)'!$S$2:$S$893) -> 351
A6: Total | B6: =SUM(B3:B5) -> 892 | C6: =SUM(C3:C5) -> 1.6937042e+09
A8: BDRs de ação por setor
A9: Setor (pt-BR) | B9: Qtd. | C9: Volume financeiro aprox. (R$)
A10: Finanças | B10: =COUNTIFS('BDRs (892)'!$C$2:$C$893,"BDR de ação",'BDRs (892)'!$E$2:$E$893,A10) -> 125 | C10: =SUMIFS('BDRs (892)'!$S$2:$S$893,'BDRs (892)'!$C$2:$C$893,"BDR de ação",'BDRs (892)'!$E$2:$E$893,A10) -> 3.7458288e+08
A11: Serviços de tecnologia | B11: =COUNTIFS('BDRs (892)'!$C$2:$C$893,"BDR de ação",'BDRs (892)'!$E$2:$E$893,A11) -> 108 | C11: =SUMIFS('BDRs (892)'!$S$2:$S$893,'BDRs (892)'!$C$2:$C$893,"BDR de ação",'BDRs (892)'!$E$2:$E$893,A11) -> 3.0511285e+08
A12: Tecnologia eletrônica | B12: =COUNTIFS('BDRs (892)'!$C$2:$C$893,"BDR de ação",'BDRs (892)'!$E$2:$E$893,A12) -> 63 | C12: =SUMIFS('BDRs (892)'!$S$2:$S$893,'BDRs (892)'!$C$2:$C$893,"BDR de ação",'BDRs (892)'!$E$2:$E$893,A12) -> 2.5859676e+08
A13: Tecnologia em saúde | B13: =COUNTIFS('BDRs (892)'!$C$2:$C$893,"BDR de ação",'BDRs (892)'!$E$2:$E$893,A13) -> 59 | C13: =SUMIFS('BDRs (892)'!$S$2:$S$893,'BDRs (892)'!$C$2:$C$893,"BDR de ação",'BDRs (892)'!$E$2:$E$893,A13) -> 11557487
A14: Varejo | B14: =COUNTIFS('BDRs (892)'!$C$2:$C$893,"BDR de ação",'BDRs (892)'!$E$2:$E$893,A14) -> 41 | C14: =SUMIFS('BDRs (892)'!$S$2:$S$893,'BDRs (892)'!$C$2:$C$893,"BDR de ação",'BDRs (892)'!$E$2:$E$893,A14) -> 1.6371e+08
A15: Bens de consumo não duráveis | B15: =COUNTIFS('BDRs (892)'!$C$2:$C$893,"BDR de ação",'BDRs (892)'!$E$2:$E$893,A15) -> 39 | C15: =SUMIFS('BDRs (892)'!$S$2:$S$893,'BDRs (892)'!$C$2:$C$893,"BDR de ação",'BDRs (892)'!$E$2:$E$893,A15) -> 2.1946989e+08
A16: Serviços ao consumidor | B16: =COUNTIFS('BDRs (892)'!$C$2:$C$893,"BDR de ação",'BDRs (892)'!$E$2:$E$893,A16) -> 33 | C16: =SUMIFS('BDRs (892)'!$S$2:$S$893,'BDRs (892)'!$C$2:$C$893,"BDR de ação",'BDRs (892)'!$E$2:$E$893,A16) -> 9165862.5
A17: Bens de produção | B17: =COUNTIFS('BDRs (892)'!$C$2:$C$893,"BDR de ação",'BDRs (892)'!$E$2:$E$893,A17) -> 31 | C17: =SUMIFS('BDRs (892)'!$S$2:$S$893,'BDRs (892)'!$C$2:$C$893,"BDR de ação",'BDRs (892)'!$E$2:$E$893,A17) -> 3197395.2
A18: Mineração e metais | B18: =COUNTIFS('BDRs (892)'!$C$2:$C$893,"BDR de ação",'BDRs (892)'!$E$2:$E$893,A18) -> 20 | C18: =SUMIFS('BDRs (892)'!$S$2:$S$893,'BDRs (892)'!$C$2:$C$893,"BDR de ação",'BDRs (892)'!$E$2:$E$893,A18) -> 1.6223797e+08
A19: Indústria de transformação | B19: =COUNTIFS('BDRs (892)'!$C$2:$C$893,"BDR de ação",'BDRs (892)'!$E$2:$E$893,A19) -> 19 | C19: =SUMIFS('BDRs (892)'!$S$2:$S$893,'BDRs (892)'!$C$2:$C$893,"BDR de ação",'BDRs (892)'!$E$2:$E$893,A19) -> 624403.95
A20: Utilidade pública | B20: =COUNTIFS('BDRs (892)'!$C$2:$C$893,"BDR de ação",'BDRs (892)'!$E$2:$E$893,A20) -> 19 | C20: =SUMIFS('BDRs (892)'!$S$2:$S$893,'BDRs (892)'!$C$2:$C$893,"BDR de ação",'BDRs (892)'!$E$2:$E$893,A20) -> 775770.82
A21: Transporte | B21: =COUNTIFS('BDRs (892)'!$C$2:$C$893,"BDR de ação",'BDRs (892)'!$E$2:$E$893,A21) -> 19 | C21: =SUMIFS('BDRs (892)'!$S$2:$S$893,'BDRs (892)'!$C$2:$C$893,"BDR de ação",'BDRs (892)'!$E$2:$E$893,A21) -> 5125837.3
... A28: Distribuição | B28: =COUNTIFS('BDRs (892)'!$C$2:$C$893,"BDR de ação",'BDRs (892)'!$E$2:$E$893,A28) -> 8 | C28: =SUMIFS('BDRs (892)'!$S$2:$S$893,'BDRs (892)'!$C$2:$C$893,"BDR de ação",'BDRs (892)'!$E$2:$E$893,A28) -> 271142.43
A29: Total | B29: =SUM(B10:B28) -> 668 | C29: =SUM(C10:C28) -> 1.6592861e+09
