Workbook

Sheet Leia-me
A1: Grupos (conglomerados) — Emissoras e Distribuidoras de Renda Fixa
A2: Gerado em 09/10/2026 no levantamento do escopo "Emissoras de Renda Fixa PrimeVest". Revisado no mesmo dia com as decisões abaixo.
A4: Fonte
A5: BCB — IF.data, cadastro (Olinda: IFDATA/IfDataCadastro), data-base 06/2026. Histórico das inativas: bases 12/2018, 12/2020, 12/2022 e 12/2024.
A6: Grupo = conglomerado prudencial do BCB (o mesmo critério do FGC).
A8: Decisões (09/10/2026)
A9: Todo conglomerado do BCB vira grupo, inclusive os de uma empresa só.
A10: Nome do grupo = coluna "Nome PrimeVest": a sugestão, sem curadoria. Origem "manual" = escolhida no levantamento (aceita pelo Guilherme); "automática" = nome do BCB sem siglas societárias.
A11: Empresas inativas são associadas ao grupo que tinham (aba "Inativas — grupo antigo"). Grupos que já não existem na base atual entram como "Extinto".
A12: Empresas só da CVM (securitizadoras, companhias de debênture) não têm grupo no BCB; podem ser associadas a um grupo por curadoria.
A13: Cooperativas de crédito não têm conglomerado prudencial no BCB (o agrupamento natural é o sistema: Sicoob, Sicredi, Unicred) — fora desta planilha.
A15: Colunas
... A17: "Qtde empresas" é fórmula (CONT.SE na aba Empresas). Situação (BCB): Ativa, Inativa, Liquidação extrajudicial, Liquidação ordinária, Falência.

Sheet Grupos
A1: Tipo | B1: Relevante RF | C1: Código grupo | D1: Nome BCB | E1: Nome PrimeVest | F1: Origem do nome | G1: CNPJ raiz líder | H1: Empresa líder | I1: Qtde empresas | J1: Empresas do grupo
A2: Várias empresas | B2: Sim | C2: C0080312 | D2: ABC-BRASIL - PRUDENCIAL | E2: ABC Brasil | F2: manual | G2: 28195667 | H2: BANCO ABC BRASIL S.A. | I2: =COUNTIF(Empresas!$A$2:$A$965,C2) -> 2 | J2: ABC BRASIL DISTRIBUIDORA DE TÍTULOS E VALORES MOBILIÁRIOS S.A.; BANCO ABC BRASIL S.A.
A3: Várias empresas | B3: Sim | C3: C0081579 | D3: BCO ABN AMRO CLEARING - PRUDENCIAL | E3: ABN AMRO | F3: manual | G3: 03532415 | H3: BANCO ABN AMRO CLEARING S.A. | I3: =COUNTIF(Empresas!$A$2:$A$965,C3) -> 2 | J3: ABN AMRO CLEARING CORRETORA DE TÍTULOS E VALORES MOBILIÁRIOS LTDA.; BANCO ABN AMRO CLEARING S.A.
A4: Várias empresas | B4: Sim | C4: C0083539 | D4: BANCO AFINZ BM - PRUDENCIAL | E4: Afinz | F4: manual | G4: 04814563 | H4: BANCO AFINZ S.A. - BANCO MÚLTIPLO | I4: =COUNTIF(Empresas!$A$2:$A$965,C4) -> 2 | J4: AFINZ INSTITUIÇÃO DE PAGAMENTO S.A.; BANCO AFINZ S.A. - BANCO MÚLTIPLO
A5: Várias empresas | B5: Sim | C5: C0083694 | D5: AGIBANK - PRUDENCIAL | E5: Agibank | F5: manual | G5: 10664513 | H5: BANCO AGIBANK S.A. | I5: =COUNTIF(Empresas!$A$2:$A$965,C5) -> 2 | J5: AGI FINANCEIRA S.A. - SOCIEDADE DE CRÉDITO, FINANCIAMENTO E INVESTIMENTO; BANCO AGIBANK S.A.
A6: Várias empresas | B6: Sim | C6: C0081256 | D6: ANDBANK - PRUDENCIAL | E6: Andbank | F6: manual | G6: 48795256 | H6: BANCO ANDBANK (BRASIL) S.A. | I6: =COUNTIF(Empresas!$A$2:$A$965,C6) -> 3 | J6: ANDBANK DISTRIBUIDORA DE TÍTULOS E VALORES MOBILIÁRIOS LTDA.; BANCO ANDBANK (BRASIL) S.A.; CREDITAS SOCIEDADE DE CRÉDITO DIRETO S.A.
A7: Várias empresas | B7: Sim | C7: C0085771 | D7: ASAAS GESTAO FINANCEIRA IP - PRUDENCIAL | E7: Asaas | F7: manual | G7: 19540550 | H7: ASAAS GESTÃO FINANCEIRA INSTITUIÇÃO DE PAGAMENTO S.A. | I7: =COUNTIF(Empresas!$A$2:$A$965,C7) -> 2 | J7: ASAAS GESTÃO FINANCEIRA INSTITUIÇÃO DE PAGAMENTO S.A.; ASAAS SOCIEDADE DE CRÉDITO, FINANCIAMENTO E INVESTIMENTO S.A.
A8: Várias empresas | B8: Sim | C8: C0081225 | D8: BANCO B3 - PRUDENCIAL | E8: B3 | F8: manual | G8: 00997185 | H8: BANCO B3 S.A. | I8: =COUNTIF(Empresas!$A$2:$A$965,C8) -> 2 | J8: B3 INSTITUICAO DE PAGAMENTO LTDA; BANCO B3 S.A.
A9: Várias empresas | B9: Sim | C9: C0080329 | D9: BB - PRUDENCIAL | E9: Banco do Brasil | F9: manual | G9: 00000000 | H9: BANCO DO BRASIL S.A. | I9: =COUNTIF(Empresas!$A$2:$A$965,C9) -> 7 | J9: BANCO DO BRASIL S.A.; BB ADMINISTRADORA DE CARTOES DE CREDITO S A; BB ADMINISTRADORA DE CONSORCIOS S.A.; BB GESTÃO DE RECURSOS - DISTRIBUIDORA DE TÍTULOS E VALORES MOBILIÁRIOS S.A.; BB-BANCO DE INVESTIMENTO S/A; BB-LEASING S/A ARRENDAMENTO MERCANTIL; BESC-DISTRIBUIDORA DE TITULOS E VALORES MOBILIARIOS SA-BESCVAL
A10: Várias empresas | B10: Sim | C10: C0080477 | D10: INDUSTRIAL DO BRASIL - PRUDENCIAL | E10: Banco Industrial | F10: manual | G10: 31895683 | H10: BANCO INDUSTRIAL DO BRASIL S.A. | I10: =COUNTIF(Empresas!$A$2:$A$965,C10) -> 2 | J10: BANCO INDUSTRIAL DO BRASIL S.A.; INDUSTRIAL DO BRASIL DISTRIBUIDORA DE TÍTULOS E VALORES MOBILIÁRIOS LTDA.
A11: Várias empresas | B11: Sim | C11: C0081634 | D11: BCO DO EST. DE SE S.A. - PRUDENCIAL | E11: Banese | F11: manual | G11: 13009717 | H11: BANCO DO ESTADO DE SERGIPE S.A. | I11: =COUNTIF(Empresas!$A$2:$A$965,C11) -> 2 | J11: BANCO DO ESTADO DE SERGIPE S.A.; MULVI INSTITUICAO DE PAGAMENTO S.A.
A12: Várias empresas | B12: Sim | C12: C0080147 | D12: BANESTES - PRUDENCIAL | E12: Banestes | F12: manual | G12: 28127603 | H12: BANESTES S.A. BANCO DO ESTADO DO ESPIRITO SANTO | I12: =COUNTIF(Empresas!$A$2:$A$965,C12) -> 2 | J12: BANESTES DISTRIBUIDORA DE TITULOS E VALORES MOBILIARIOS S/A; BANESTES S.A. BANCO DO ESTADO DO ESPIRITO SANTO
A13: Várias empresas | B13: Sim | C13: C0080556 | D13: BOFA MERRILL LYNCH - PRUDENCIAL | E13: Bank of America | F13: manual | G13: 62073200 | H13: BANK OF AMERICA MERRILL LYNCH BANCO MÚLTIPLO S.A. | I13: =COUNTIF(Empresas!$A$2:$A$965,C13) -> 2 | J13: BANK OF AMERICA MERRILL LYNCH BANCO MÚLTIPLO S.A.; MERRILL LYNCH S.A. CORRETORA DE TÍTULOS E VALORES MOBILIÁRIOS
... A109: Várias empresas | B109: Sim | C109: C0083584 | D109: ZEMA CFI - PRUDENCIAL | E109: Zema | F109: automática | G109: 05351887 | H109: ZEMA CRÉDITO, FINANCIAMENTO E INVESTIMENTO S/A | I109: =COUNTIF(Empresas!$A$2:$A$965,C109) -> 2 | J109: ZEMA ADMINISTRADORA DE CONSÓRCIO LTDA; ZEMA CRÉDITO, FINANCIAMENTO E INVESTIMENTO S/A
A110: Extinto | B110: Sim | C110: C0080367 | D110: BANCO MASTER (bases antigas) | E110: Banco Master | F110: manual | I110: =COUNTIF(Empresas!$A$2:$A$965,C110) -> 8 | J110: BANCO LETSBANK S.A. - EM LIQUIDAÇÃO EXTRAJUDICIAL; BANCO MASTER DE INVESTIMENTO S.A. - EM LIQUIDAÇÃO EXTRAJUDICIAL; BANCO MASTER MÚLTIPLO S.A. - EM LIQUIDAÇÃO EXTRAJUDICIAL; BANCO MASTER S/A - EM LIQUIDAÇÃO EXTRAJUDICIAL; BANCO PLENO S.A. - EM LIQUIDAÇÃO EXTRAJUDICIAL; MASTER S/A CORRETORA DE CÂMBIO, TÍTULOS E VALORES MOBILIÁRIOS - EM LIQUIDAÇÃO EXTRAJUDICIAL; PLENO DISTRIBUIDORA DE TÍTULOS E VALORES MOBILIÁRIOS S.A. - EM LIQUIDAÇÃO EXTRAJUDICIAL; WILL FINANCEIRA S.A. CRÉDITO, FINANCIAMENTO E INVESTIMENTO - EM LIQUIDAÇÃO EXTRAJUDICIAL
A111: Extinto | B111: Sim | C111: C0081005 | D111: DACASA FINANCEIRA (bases antigas) | E111: Dacasa Financeira | F111: manual | I111: =COUNTIF(Empresas!$A$2:$A$965,C111) -> 2 | J111: DACASA FINANCEIRA S/A - SOCIEDADE DE CRÉDITO, FINANCIAMENTO E INVESTIMENTO; UNILETRA CORRETORA DE CÂMBIO, TÍTULOS E VALORES MOBILIÁRIOS S.A.
A112: Uma empresa | B112: Sim | C112: C0085977 | D112: ACTIVTRADES CCTVM - PRUDENCIAL | E112: Activtrades | F112: automática | G112: 43050917 | H112: ACTIVTRADES CORRETORA DE CÂMBIO, TÍTULOS E VALORES MOBILIÁRIOS LTDA. | I112: =COUNTIF(Empresas!$A$2:$A$965,C112) -> 1 | J112: ACTIVTRADES CORRETORA DE CÂMBIO, TÍTULOS E VALORES MOBILIÁRIOS LTDA.
A113: Uma empresa | B113: Sim | C113: C0087243 | D113: ACTUAL DTVM - PRUDENCIAL | E113: Actual | F113: automática | G113: 44782130 | H113: ACTUAL DISTRIBUIDORA DE TÍTULOS E VALORES MOBILIÁRIOS S.A. | I113: =COUNTIF(Empresas!$A$2:$A$965,C113) -> 1 | J113: ACTUAL DISTRIBUIDORA DE TÍTULOS E VALORES MOBILIÁRIOS S.A.
A114: Uma empresa | B114: Sim | C114: C0083618 | D114: AGORACRED S/A SCFI - PRUDENCIAL | E114: Agoracred | F114: automática | G114: 36321990 | H114: AGORACRED S/A SOCIEDADE DE CRÉDITO, FINANCIAMENTO E INVESTIMENTO | I114: =COUNTIF(Empresas!$A$2:$A$965,C114) -> 1 | J114: AGORACRED S/A SOCIEDADE DE CRÉDITO, FINANCIAMENTO E INVESTIMENTO
A115: Uma empresa | B115: Sim | C115: C0085867 | D115: AGROLEND SCFI - PRUDENCIAL | E115: Agrolend | F115: automática | G115: 43774196 | H115: AGROLEND SOCIEDADE DE CREDITO, FINANCIAMENTO E INVESTIMENTO S.A. | I115: =COUNTIF(Empresas!$A$2:$A$965,C115) -> 1 | J115: AGROLEND SOCIEDADE DE CREDITO, FINANCIAMENTO E INVESTIMENTO S.A.
A116: Uma empresa | B116: Sim | C116: C0084734 | D116: AL5 S.A. SCFI - PRUDENCIAL | E116: Al5 | F116: automática | G116: 27214112 | H116: AL5 S.A. SOCIEDADE DE CRÉDITO, FINANCIAMENTO E INVESTIMENTO | I116: =COUNTIF(Empresas!$A$2:$A$965,C116) -> 1 | J116: AL5 S.A. SOCIEDADE DE CRÉDITO, FINANCIAMENTO E INVESTIMENTO
A117: Uma empresa | B117: Sim | C117: C0082516 | D117: AMARIL FRANKLIN CTV LTDA - PRUDENCIAL | E117: Amaril Franklin | F117: automática | G117: 17312661 | H117: AMARIL FRANKLIN CORRETORA DE TÍTULOS E VALORES LTDA | I117: =COUNTIF(Empresas!$A$2:$A$965,C117) -> 1 | J117: AMARIL FRANKLIN CORRETORA DE TÍTULOS E VALORES LTDA
A118: Uma empresa | B118: Sim | C118: C0088871 | D118: AMICORP DTVM - PRUDENCIAL | E118: Amicorp | F118: automática | G118: 54211458 | H118: AMICORP DISTRIBUIDORA DE TÍTULOS E VALORES MOBILIÁRIOS LTDA. | I118: =COUNTIF(Empresas!$A$2:$A$965,C118) -> 1 | J118: AMICORP DISTRIBUIDORA DE TÍTULOS E VALORES MOBILIÁRIOS LTDA.
A119: Uma empresa | B119: Sim | C119: C0086608 | D119: ASA SCFI - PRUDENCIAL | E119: ASA | F119: automática | G119: 48703388 | H119: ASA SOCIEDADE DE CRÉDITO FINANCIAMENTO E INVESTIMENTO S.A. | I119: =COUNTIF(Empresas!$A$2:$A$965,C119) -> 1 | J119: ASA SOCIEDADE DE CRÉDITO FINANCIAMENTO E INVESTIMENTO S.A.
A120: Uma empresa | B120: Sim | C120: C0082547 | D120: ATIVA S.A. CTCV - PRUDENCIAL | E120: Ativa Investimentos | F120: manual | G120: 33775974 | H120: ATIVA INVESTIMENTOS S.A. CORRETORA DE TÍTULOS, CÂMBIO E VALORES | I120: =COUNTIF(Empresas!$A$2:$A$965,C120) -> 1 | J120: ATIVA INVESTIMENTOS S.A. CORRETORA DE TÍTULOS, CÂMBIO E VALORES
A121: Uma empresa | B121: Sim | C121: C0084325 | D121: AZIMUT BRASIL DTVM - PRUDENCIAL | E121: Azimut Brasil | F121: automática | G121: 18684408 | H121: AZIMUT BRASIL DISTRIBUIDORA DE TÍTULOS E VALORES MOBILIÁRIOS LTDA | I121: =COUNTIF(Empresas!$A$2:$A$965,C121) -> 1 | J121: AZIMUT BRASIL DISTRIBUIDORA DE TÍTULOS E VALORES MOBILIÁRIOS LTDA
A122: Uma empresa | B122: Sim | C122: C0085719 | D122: AZUMI DTVM PRUDENCIAL | E122: Azumi | F122: automática | G122: 40434681 | H122: AZUMI DISTRIBUIDORA DE TÍTULOS E VALORES MOBILIÁRIOS LTDA. | I122: =COUNTIF(Empresas!$A$2:$A$965,C122) -> 1 | J122: AZUMI DISTRIBUIDORA DE TÍTULOS E VALORES MOBILIÁRIOS LTDA.
A123: Uma empresa | B123: Sim | C123: C0081201 | D123: BCO ARBI S.A. - PRUDENCIAL | E123: Banco Arbi | F123: automática | G123: 54403563 | H123: BANCO ARBI S.A. | I123: =COUNTIF(Empresas!$A$2:$A$965,C123) -> 1 | J123: BANCO ARBI S.A.
... A660: Uma empresa | B660: Não | C660: C0087638 | D660: ÓPERA SCD - PRUDENCIAL | E660: Ópera | F660: automática | G660: 55841657 | H660: ÓPERA SOCIEDADE DE CRÉDITO DIRETO S.A. | I660: =COUNTIF(Empresas!$A$2:$A$965,C660) -> 1 | J660: ÓPERA SOCIEDADE DE CRÉDITO DIRETO S.A.

Sheet Empresas
A1: Código grupo | B1: Grupo (Nome PrimeVest) | C1: CNPJ raiz | D1: Razão social | E1: Segmento | F1: Situação | G1: Líder do grupo | H1: Origem do vínculo
A2: C0087597 | B2: 3x | C2: 36010822 | D2: 3X INSTITUIÇÃO DE PAGAMENTO LTDA | E2: Instituição de Pagamento | F2: Ativa | G2: Sim | H2: BCB 06/2026
A3: C0088606 | B3: 8b Servicos Financeiros | C3: 55586562 | D3: 8B SERVICOS FINANCEIROS INSTITUICAO DE PAGAMENTO S/A | E3: Instituição de Pagamento | F3: Inativa | G3: Sim | H3: BCB 06/2026
A4: C0087793 | B4: 99Pay | C4: 24313102 | D4: 99PAY INSTITUICAO DE PAGAMENTO S.A. | E4: Instituição de Pagamento | F4: Ativa | G4: Sim | H4: BCB 06/2026
A5: C0087793 | B5: 99Pay | C5: 59379565 | D5: 99PAY SOCIEDADE DE CRÉDITO DIRETO S.A. | E5: Sociedade de Crédito Direto | F5: Ativa | H5: BCB 06/2026
A6: C0087504 | B6: A27 | C6: 35534511 | D6: A27 INSTITUICAO DE PAGAMENTOS S/A | E6: Instituição de Pagamento | F6: Ativa | G6: Sim | H6: BCB 06/2026
A7: C0086512 | B7: A55 | C7: 48756121 | D7: A55 SOCIEDADE DE CRÉDITO DIRETO S.A. | E7: Sociedade de Crédito Direto | F7: Ativa | G7: Sim | H7: BCB 06/2026
A8: C0080312 | B8: ABC Brasil | C8: 28195667 | D8: BANCO ABC BRASIL S.A. | E8: Banco Múltiplo | F8: Ativa | G8: Sim | H8: BCB 06/2026
A9: C0080312 | B9: ABC Brasil | C9: 33817677 | D9: ABC BRASIL DISTRIBUIDORA DE TÍTULOS E VALORES MOBILIÁRIOS S.A. | E9: Sociedade Distribuidora de TVM | F9: Ativa | H9: BCB 06/2026
A10: C0081579 | B10: ABN AMRO | C10: 03532415 | D10: BANCO ABN AMRO CLEARING S.A. | E10: Banco Múltiplo | F10: Ativa | G10: Sim | H10: BCB 06/2026
A11: C0081579 | B11: ABN AMRO | C11: 44527444 | D11: ABN AMRO CLEARING CORRETORA DE TÍTULOS E VALORES MOBILIÁRIOS LTDA. | E11: Sociedade Corretora de TVM | F11: Ativa | H11: BCB 06/2026
A12: C0087559 | B12: Accesstage | C12: 46410407 | D12: ACCESSTAGE INSTITUIÇÃO DE PAGAMENTO LTDA. | E12: Instituição de Pagamento | F12: Inativa | G12: Sim | H12: BCB 06/2026
A13: C0085331 | B13: Accredito | C13: 37715993 | D13: ACCREDITO - SOCIEDADE DE CRÉDITO DIRETO S.A. | E13: Sociedade de Crédito Direto | F13: Ativa | G13: Sim | H13: BCB 06/2026
A14: C0086093 | B14: ACG | C14: 10868663 | D14: ACG INSTITUIÇÃO DE PAGAMENTO S.A. | E14: Instituição de Pagamento | F14: Ativa | G14: Sim | H14: BCB 06/2026
A15: C0085977 | B15: Activtrades | C15: 43050917 | D15: ACTIVTRADES CORRETORA DE CÂMBIO, TÍTULOS E VALORES MOBILIÁRIOS LTDA. | E15: Sociedade Corretora de TVM | F15: Ativa | G15: Sim | H15: BCB 06/2026
A16: C0087243 | B16: Actual | C16: 44782130 | D16: ACTUAL DISTRIBUIDORA DE TÍTULOS E VALORES MOBILIÁRIOS S.A. | E16: Sociedade Distribuidora de TVM | F16: Ativa | G16: Sim | H16: BCB 06/2026
A17: C0087401 | B17: Adyen do Brasil | C17: 14796606 | D17: ADYEN DO BRASIL INSTITUICAO DE PAGAMENTO LTDA. | E17: Instituição de Pagamento | F17: Ativa | G17: Sim | H17: BCB 06/2026
A18: C0081153 | B18: AF Desenvolve SP | C18: 10663610 | D18: DESENVOLVE SP - AGÊNCIA DE FOMENTO DO ESTADO DE SÃO PAULO S.A. | E18: Agência de Fomento | F18: Ativa | G18: Sim | H18: BCB 06/2026
A19: C0081074 | B19: AF do Estado de SC | C19: 82937293 | D19: AGÊNCIA DE FOMENTO DO ESTADO DE SANTA CATARINA S.A.-BADESC | E19: Agência de Fomento | F19: Ativa | G19: Sim | H19: BCB 06/2026
A20: C0081177 | B20: AF Estado de Pernambuco | C20: 13178690 | D20: AGÊNCIA DE FOMENTO DO ESTADO DE PERNAMBUCO S.A. | E20: Agência de Fomento | F20: Ativa | G20: Sim | H20: BCB 06/2026
A21: C0081115 | B21: AF Paraná | C21: 03584906 | D21: AGÊNCIA DE FOMENTO DO PARANÁ S.A. | E21: Agência de Fomento | F21: Ativa | G21: Sim | H21: BCB 06/2026
A22: C0081081 | B22: Afal | C22: 10769660 | D22: AGÊNCIA DE FOMENTO DE ALAGOAS S.A. | E22: Agência de Fomento | F22: Ativa | G22: Sim | H22: BCB 06/2026
A23: C0081108 | B23: Afeam | C23: 03183937 | D23: AGÊNCIA DE FOMENTO DO ESTADO DO AMAZONAS S.A. - AFEAM | E23: Agência de Fomento | F23: Ativa | G23: Sim | H23: BCB 06/2026
A24: C0083539 | B24: Afinz | C24: 04814563 | D24: BANCO AFINZ S.A. - BANCO MÚLTIPLO | E24: Banco Múltiplo | F24: Ativa | G24: Sim | H24: BCB 06/2026
A25: C0083539 | B25: Afinz | C25: 60114865 | D25: AFINZ INSTITUIÇÃO DE PAGAMENTO S.A. | E25: Instituição de Pagamento | F25: Ativa | H25: BCB 06/2026
A26: C0081043 | B26: Agencia de Fomento do RN | C26: 03848103 | D26: AGENCIA DE FOMENTO DO RIO GRANDE DO NORTE S.A. | E26: Agência de Fomento | F26: Ativa | G26: Sim | H26: BCB 06/2026
A27: C0081139 | B27: Agencia Fomento Est RJ | C27: 05940203 | D27: AGENCIA DE FOMENTO DO ESTADO DO RIO DE JANEIRO S.A. | E27: Agência de Fomento | F27: Ativa | G27: Sim | H27: BCB 06/2026
A28: C0081050 | B28: Agencia Fomento Goias | C28: 03918382 | D28: AGENCIA DE FOMENTO DE GOIAS S/A | E28: Agência de Fomento | F28: Ativa | G28: Sim | H28: BCB 06/2026
A29: C0081029 | B29: Agencia Fomento RS Badesul | C29: 02885855 | D29: BADESUL DESENVOLVIMENTO S.A - AGÊNCIA DE FOMENTO/RS | E29: Agência de Fomento | F29: Ativa | G29: Sim | H29: BCB 06/2026
A30: C0083694 | B30: Agibank | C30: 10664513 | D30: BANCO AGIBANK S.A. | E30: Banco Comercial | F30: Ativa | G30: Sim | H30: BCB 06/2026
A31: C0083694 | B31: Agibank | C31: 13660104 | D31: AGI FINANCEIRA S.A. - SOCIEDADE DE CRÉDITO, FINANCIAMENTO E INVESTIMENTO | E31: Sociedade de Crédito, Financiamento e Investimento | F31: Ativa | H31: BCB 06/2026
A32: C0082035 | B32: AGK | C32: 00250699 | D32: AGK CORRETORA DE CAMBIO S.A. | E32: Sociedade Corretora de Câmbio | F32: Ativa | G32: Sim | H32: BCB 06/2026
A33: C0083618 | B33: Agoracred | C33: 36321990 | D33: AGORACRED S/A SOCIEDADE DE CRÉDITO, FINANCIAMENTO E INVESTIMENTO | E33: Sociedade de Crédito, Financiamento e Investimento | F33: Ativa | G33: Sim | H33: BCB 06/2026
A34: C0085867 | B34: Agrolend | C34: 43774196 | D34: AGROLEND SOCIEDADE DE CREDITO, FINANCIAMENTO E INVESTIMENTO S.A. | E34: Sociedade de Crédito, Financiamento e Investimento | F34: Ativa | G34: Sim | H34: BCB 06/2026
A35: C0081146 | B35: Agência de Fomento Mato Grosso | C35: 06284531 | D35: AGÊNCIA DE FOMENTO DO ESTADO DE MATO GROSSO S/A - DESENVOLVE MT | E35: Agência de Fomento | F35: Ativa | G35: Sim | H35: BCB 06/2026
A36: C0081098 | B36: Agência Fomento Amapa | C36: 02929977 | D36: AGENCIA DE FOMENTO DO AMAPA S.A. | E36: Agência de Fomento | F36: Ativa | G36: Sim | H36: BCB 06/2026
A37: C0081036 | B37: Agência Fomento Estado de Roraima | C37: 03058464 | D37: AGENCIA DE FOMENTO DO ESTADO DE RORAIMA S/A | E37: Agência de Fomento | F37: Ativa | G37: Sim | H37: BCB 06/2026
A38: C0081122 | B38: Agência Fomento Estado do Tocantins | C38: 05474540 | D38: AGÊNCIA DE FOMENTO DO ESTADO DO TOCANTINS S.A. | E38: Agência de Fomento | F38: Ativa | G38: Sim | H38: BCB 06/2026
A39: C0084734 | B39: Al5 | C39: 27214112 | D39: AL5 S.A. SOCIEDADE DE CRÉDITO, FINANCIAMENTO E INVESTIMENTO | E39: Sociedade de Crédito, Financiamento e Investimento | F39: Ativa | G39: Sim | H39: BCB 06/2026
A40: C0085379 | B40: Alesta Sociedade de Credito Direto | C40: 38316293 | D40: ALESTA SOCIEDADE DE CREDITO DIRETO S.A. | E40: Sociedade de Crédito Direto | F40: Ativa | G40: Sim | H40: BCB 06/2026
...

Sheet Inativas — grupo antigo
A1: CNPJ raiz | B1: Razão social | C1: Segmento | D1: Situação hoje | E1: Última base com grupo | F1: Código grupo | G1: Grupo associado (Nome PrimeVest) | H1: Grupo ainda existe?
A2: 82518523 | B2: BESC-DISTRIBUIDORA DE TITULOS E VALORES MOBILIARIOS SA-BESCVAL | C2: Sociedade Distribuidora de TVM | D2: Inativa | E2: 12/2020 | F2: C0080329 | G2: Banco do Brasil | H2: Sim
A3: 58497702 | B3: BANCO LETSBANK S.A. - EM LIQUIDAÇÃO EXTRAJUDICIAL | C3: Banco Múltiplo | D3: Liquidação extrajudicial | E3: 12/2024 | F3: C0080367 | G3: Banco Master | H3: Não (extinto)
A4: 09526594 | B4: BANCO MASTER DE INVESTIMENTO S.A. - EM LIQUIDAÇÃO EXTRAJUDICIAL | C4: Banco de Investimento | D4: Liquidação extrajudicial | E4: 12/2024 | F4: C0080367 | G4: Banco Master | H4: Não (extinto)
A5: 33884941 | B5: BANCO MASTER MÚLTIPLO S.A. - EM LIQUIDAÇÃO EXTRAJUDICIAL | C5: Banco Múltiplo | D5: Liquidação extrajudicial | E5: 12/2024 | F5: C0080367 | G5: Banco Master | H5: Não (extinto)
A6: 33923798 | B6: BANCO MASTER S/A - EM LIQUIDAÇÃO EXTRAJUDICIAL | C6: Banco Comercial | D6: Liquidação extrajudicial | E6: 12/2024 | F6: C0080367 | G6: Banco Master | H6: Não (extinto)
A7: 61024352 | B7: BANCO PLENO S.A. - EM LIQUIDAÇÃO EXTRAJUDICIAL | C7: Banco Múltiplo | D7: Liquidação extrajudicial | E7: 12/2024 | F7: C0080367 | G7: Banco Master | H7: Não (extinto)
A8: 33886862 | B8: MASTER S/A CORRETORA DE CÂMBIO, TÍTULOS E VALORES MOBILIÁRIOS - EM LIQUIDAÇÃO EXTRAJUDICIAL | C8: Sociedade Corretora de TVM | D8: Liquidação extrajudicial | E8: 12/2024 | F8: C0080367 | G8: Banco Master | H8: Não (extinto)
A9: 02927433 | B9: PLENO DISTRIBUIDORA DE TÍTULOS E VALORES MOBILIÁRIOS S.A. - EM LIQUIDAÇÃO EXTRAJUDICIAL | C9: Sociedade Distribuidora de TVM | D9: Liquidação extrajudicial | E9: 12/2024 | F9: C0080367 | G9: Banco Master | H9: Não (extinto)
A10: 23862762 | B10: WILL FINANCEIRA S.A. CRÉDITO, FINANCIAMENTO E INVESTIMENTO - EM LIQUIDAÇÃO EXTRAJUDICIAL | C10: Sociedade de Crédito, Financiamento e Investimento | D10: Liquidação extrajudicial | E10: 12/2024 | F10: C0080367 | G10: Banco Master | H10: Não (extinto)
A11: 00558456 | B11: BANCO CETELEM S.A. | C11: Banco Múltiplo | D11: Inativa | E11: 12/2022 | F11: C0080673 | G11: BNP Paribas | H11: Sim
A12: 33870163 | B12: BANCO ALVORADA S.A. | C12: Banco Múltiplo | D12: Inativa | E12: 12/2018 | F12: C0080075 | G12: Bradesco | H12: Sim
... A33: 30723886 | B33: BANCO MODAL S.A. | C33: Banco Múltiplo | D33: Inativa | E33: 12/2024 | F33: C0082475 | G33: XP | H33: Sim
